<?xml version="1.0" ?>
<!-- =================================================================================== -->
<!-- |    This document was autogenerated by xacro from robot_base.urdf.xacro          | -->
<!-- |    EDITING THIS FILE BY HAND IS NOT RECOMMENDED                                 | -->
<!-- =================================================================================== -->
<robot name="robot_base">
  <link name="base_footprint">
    <visual>
      <geometry>
        <box size="0.001 0.001 0.001"/>
      </geometry>
    </visual>
  </link>
  <link name="base_link">
    <visual>
      <geometry>
        <box size="0.16 0.25 0.05"/>
      </geometry>
      <origin rpy="0 0 1.57075" xyz="0 0 0"/>
      <material name="blue">
        <color rgba="0 .5 .8 1"/>
      </material>
    </visual>
    <collision>
      <geometry>
        <box size="0.16 0.25 0.05"/>
      </geometry>
      <origin rpy="0 0 0" xyz="0 0 0"/>
    </collision>
    <inertial>
      <mass value="0.5"/>
      <inertia ixx="0.0027083333333333334" ixy="0" ixz="0" iyy="0.0036708333333333332" iyz="0" izz="0.0011708333333333334"/>
    </inertial>
  </link>
  <joint name="base_link2base_footprint" type="fixed">
    <parent link="base_footprint"/>
    <child link="base_link"/>
    <origin xyz="0 0 0.07500000000000001"/>
  </joint>
  <gazebo reference="base_link">
    <material>Gazebo/Yellow</material>
  </gazebo>
  <link name="left_front_wheel">
    <visual>
      <geometry>
        <cylinder length="0.02" radius="0.025"/>
      </geometry>
      <origin rpy="1.5707963 0.0 0.0" xyz="0.0 0.0 0.0"/>
      <material name="black">
        <color rgba="0 0 0 1"/>
      </material>
    </visual>
    <collision>
      <geometry>
        <cylinder length="0.02" radius="0.025"/>
      </geometry>
      <origin rpy="1.5707963 0.0 0.0" xyz="0.0 0.0 0.0"/>
    </collision>
    <inertial>
      <mass value="0.05"/>
      <inertia ixx="9.479166666666669e-06" ixy="0" ixz="0" iyy="9.479166666666669e-06" iyz="0" izz="1.5625000000000004e-05"/>
    </inertial>
  </link>
  <joint name="left_front_wheel2base_link" type="continuous">
    <parent link="base_link"/>
    <child link="left_front_wheel"/>
    <origin xyz="0.08 0.08 -0.025"/>
    <axis xyz="0 1 0"/>
  </joint>
  <gazebo reference="left_front_wheel">
    <material>Gazebo/Red</material>
  </gazebo>
  <link name="right_front_wheel">
    <visual>
      <geometry>
        <cylinder length="0.02" radius="0.025"/>
      </geometry>
      <origin rpy="1.5707963 0.0 0.0" xyz="0.0 0.0 0.0"/>
      <material name="black">
        <color rgba="0 0 0 1"/>
      </material>
    </visual>
    <collision>
      <geometry>
        <cylinder length="0.02" radius="0.025"/>
      </geometry>
      <origin rpy="1.5707963 0.0 0.0" xyz="0.0 0.0 0.0"/>
    </collision>
    <inertial>
      <mass value="0.05"/>
      <inertia ixx="9.479166666666669e-06" ixy="0" ixz="0" iyy="9.479166666666669e-06" iyz="0" izz="1.5625000000000004e-05"/>
    </inertial>
  </link>
  <joint name="right_front_wheel2base_link" type="continuous">
    <parent link="base_link"/>
    <child link="right_front_wheel"/>
    <origin xyz="0.08 -0.08 -0.025"/>
    <axis xyz="0 1 0"/>
  </joint>
  <gazebo reference="right_front_wheel">
    <material>Gazebo/Red</material>
  </gazebo>
  <link name="left_back_wheel">
    <visual>
      <geometry>
        <cylinder length="0.02" radius="0.025"/>
      </geometry>
      <origin rpy="1.5707963 0.0 0.0" xyz="0.0 0.0 0.0"/>
      <material name="black"/>
    </visual>
    <collision>
      <geometry>
        <cylinder length="0.02" radius="0.025"/>
      </geometry>
      <origin rpy="1.5707963 0.0 0.0" xyz="0.0 0.0 0.0"/>
    </collision>
    <inertial>
      <mass value="0.05"/>
      <inertia ixx="9.479166666666669e-06" ixy="0" ixz="0" iyy="9.479166666666669e-06" iyz="0" izz="1.5625000000000004e-05"/>
    </inertial>
  </link>
  <joint name="left_back_wheel2base_link" type="continuous">
    <parent link="base_link"/>
    <child link="left_back_wheel"/>
    <origin xyz="-0.08 0.08 -0.025"/>
    <axis xyz="0 1 0"/>
  </joint>
  <gazebo reference="left_back_wheel">
    <material>Gazebo/Red</material>
  </gazebo>
  <link name="right_back_wheel">
    <visual>
      <geometry>
        <cylinder length="0.02" radius="0.025"/>
      </geometry>
      <origin rpy="1.5707963 0.0 0.0" xyz="0.0 0.0 0.0"/>
      <material name="black"/>
    </visual>
    <collision>
      <geometry>
        <cylinder length="0.02" radius="0.025"/>
      </geometry>
      <origin rpy="1.5707963 0.0 0.0" xyz="0.0 0.0 0.0"/>
    </collision>
    <inertial>
      <mass value="0.05"/>
      <inertia ixx="9.479166666666669e-06" ixy="0" ixz="0" iyy="9.479166666666669e-06" iyz="0" izz="1.5625000000000004e-05"/>
    </inertial>
  </link>
  <joint name="right_back_wheel2base_link" type="continuous">
    <parent link="base_link"/>
    <child link="right_back_wheel"/>
    <origin xyz="-0.08 -0.08 -0.025"/>
    <axis xyz="0 1 0"/>
  </joint>
  <gazebo reference="right_back_wheel">
    <material>Gazebo/Red</material>
  </gazebo>
</robot>

